<robot name="mobile_robot">
  <link name="base_link">
    <inertial>
      <mass value="1.0" />
      <inertia  ixx="1.0" ixy="0.0"  ixz="0.0"  iyy="1.0"  iyz="0.0"  izz="1.0" />
    </inertial>
    <visual>
      <origin xyz="0 0 0"/>
      <geometry>
        <box size="0.3 0.3 0.05"/>
      </geometry>
      <material name="white">
        <color rgba="1 1 1 1"/>
      </material>
    </visual>
    <collision>
      <geometry>
        <box size="0.3 0.3 0.05"/>
      </geometry>
    </collision>
  </link>
  
  <link name="left_wheel">
    <inertial>
      <mass value="1.0" />
      <inertia  ixx="1.0" ixy="0.0"  ixz="0.0"  iyy="1.0"  iyz="0.0"  izz="1.0" />
    </inertial>
    <visual>
      <geometry>
        <cylinder length="0.05" radius="0.1"/>
      </geometry>
      <origin rpy="0 0 0" xyz="0 0 0"/>
      <material name="blue">
        <color rgba="0 0 255 1"/>
      </material>
    </visual>
    <collision>
      <geometry>
        <cylinder length="0.05" radius="0.1"/>
      </geometry>
    </collision>
  </link>
  
  <joint name="wheel_left_joint" type="continuous">
    <parent link="base_link"/>
    <child link="left_wheel"/>
    <origin xyz="0 0.175 0" rpy="1.5708 0 0"/>
    <axis xyz="0 1 0"/>
  </joint>

  <link name="right_wheel">
    <inertial>
      <mass value="1.0" />
      <inertia  ixx="1.0" ixy="0.0"  ixz="0.0"  iyy="1.0"  iyz="0.0"  izz="1.0" />
    </inertial>
    <visual>
      <geometry>
        <cylinder length="0.05" radius="0.1"/>
      </geometry>
      <origin rpy="0 0 0" xyz="0 0 0"/>
      <material name="blue">
        <color rgba="0 0 1 1"/>
      </material>
    </visual>
    <collision>
      <geometry>
        <cylinder length="0.05" radius="0.1"/>
      </geometry>
    </collision>
  </link>
  
  <joint name="wheel_right_joint" type="continuous">
    <parent link="base_link"/>
    <child link="right_wheel"/>
    <origin xyz="0 -0.175 0" rpy="1.5708 0 0"/>
    <axis xyz="0 1 0"/>
  </joint>

  <transmission name="left_wheel_transmission">
    <type>transmission_interface/SimpleTransmission</type>
    <joint name="wheel_left_joint">
      <hardwareInterface>hardware_interface/VelocityJointInterface</hardwareInterface>
    </joint>
    <actuator name="left_wheel_actuator">
      <mechanicalReduction>7</mechanicalReduction>
      <hardwareInterface>VelocityJointInterface</hardwareInterface>
    </actuator>
  </transmission>
  
  <transmission name="right_wheel_transmission">
    <type>transmission_interface/SimpleTransmission</type>
    <joint name="wheel_right_joint">
      <hardwareInterface>hardware_interface/VelocityJointInterface</hardwareInterface>
    </joint>
    <actuator name="right_wheel_actuator">
      <mechanicalReduction>7</mechanicalReduction>
      <hardwareInterface>VelocityJointInterface</hardwareInterface>
    </actuator>
  </transmission>
  
  <gazebo>
    <plugin name="gazebo_ros_control" filename="libgazebo_ros_contol.so">
    </plugin>
  </gazebo>
</robot>

